2021-04-23 17:01:03 [ERROR   ] (log.log_response) Internal Server Error: /
Traceback (most recent call last):
  File "/home/ubuntu/ScheduleBrewer/venv/lib/python3.6/site-packages/django/core/handlers/exception.py", line 47, in inner
    response = get_response(request)
  File "/home/ubuntu/ScheduleBrewer/venv/lib/python3.6/site-packages/django/core/handlers/base.py", line 167, in _get_response
    callback, callback_args, callback_kwargs = self.resolve_request(request)
  File "/home/ubuntu/ScheduleBrewer/venv/lib/python3.6/site-packages/django/core/handlers/base.py", line 290, in resolve_request
    resolver_match = resolver.resolve(request.path_info)
  File "/home/ubuntu/ScheduleBrewer/venv/lib/python3.6/site-packages/django/urls/resolvers.py", line 556, in resolve
    for pattern in self.url_patterns:
  File "/home/ubuntu/ScheduleBrewer/venv/lib/python3.6/site-packages/django/utils/functional.py", line 48, in __get__
    res = instance.__dict__[self.name] = self.func(instance)
  File "/home/ubuntu/ScheduleBrewer/venv/lib/python3.6/site-packages/django/urls/resolvers.py", line 598, in url_patterns
    patterns = getattr(self.urlconf_module, "urlpatterns", self.urlconf_module)
  File "/home/ubuntu/ScheduleBrewer/venv/lib/python3.6/site-packages/django/utils/functional.py", line 48, in __get__
    res = instance.__dict__[self.name] = self.func(instance)
  File "/home/ubuntu/ScheduleBrewer/venv/lib/python3.6/site-packages/django/urls/resolvers.py", line 591, in urlconf_module
    return import_module(self.urlconf_name)
  File "/usr/lib/python3.6/importlib/__init__.py", line 126, in import_module
    return _bootstrap._gcd_import(name[level:], package, level)
  File "<frozen importlib._bootstrap>", line 994, in _gcd_import
  File "<frozen importlib._bootstrap>", line 971, in _find_and_load
  File "<frozen importlib._bootstrap>", line 955, in _find_and_load_unlocked
  File "<frozen importlib._bootstrap>", line 665, in _load_unlocked
  File "<frozen importlib._bootstrap_external>", line 678, in exec_module
  File "<frozen importlib._bootstrap>", line 219, in _call_with_frames_removed
  File "/home/ubuntu/ScheduleBrewer/ScheduleBrewer/ScheduleBrewer/urls.py", line 18, in <module>
    from CourseBrowser import views
  File "/home/ubuntu/ScheduleBrewer/ScheduleBrewer/CourseBrowser/views.py", line 73
    logger.info("else")
                      ^
TabError: inconsistent use of tabs and spaces in indentation
2021-04-23 17:01:03 [ERROR   ] (log.log_response) Internal Server Error: /
Traceback (most recent call last):
  File "/home/ubuntu/ScheduleBrewer/venv/lib/python3.6/site-packages/django/core/handlers/exception.py", line 47, in inner
    response = get_response(request)
  File "/home/ubuntu/ScheduleBrewer/venv/lib/python3.6/site-packages/django/core/handlers/base.py", line 167, in _get_response
    callback, callback_args, callback_kwargs = self.resolve_request(request)
  File "/home/ubuntu/ScheduleBrewer/venv/lib/python3.6/site-packages/django/core/handlers/base.py", line 290, in resolve_request
    resolver_match = resolver.resolve(request.path_info)
  File "/home/ubuntu/ScheduleBrewer/venv/lib/python3.6/site-packages/django/urls/resolvers.py", line 556, in resolve
    for pattern in self.url_patterns:
  File "/home/ubuntu/ScheduleBrewer/venv/lib/python3.6/site-packages/django/utils/functional.py", line 48, in __get__
    res = instance.__dict__[self.name] = self.func(instance)
  File "/home/ubuntu/ScheduleBrewer/venv/lib/python3.6/site-packages/django/urls/resolvers.py", line 598, in url_patterns
    patterns = getattr(self.urlconf_module, "urlpatterns", self.urlconf_module)
  File "/home/ubuntu/ScheduleBrewer/venv/lib/python3.6/site-packages/django/utils/functional.py", line 48, in __get__
    res = instance.__dict__[self.name] = self.func(instance)
  File "/home/ubuntu/ScheduleBrewer/venv/lib/python3.6/site-packages/django/urls/resolvers.py", line 591, in urlconf_module
    return import_module(self.urlconf_name)
  File "/usr/lib/python3.6/importlib/__init__.py", line 126, in import_module
    return _bootstrap._gcd_import(name[level:], package, level)
  File "<frozen importlib._bootstrap>", line 994, in _gcd_import
  File "<frozen importlib._bootstrap>", line 971, in _find_and_load
  File "<frozen importlib._bootstrap>", line 955, in _find_and_load_unlocked
  File "<frozen importlib._bootstrap>", line 665, in _load_unlocked
  File "<frozen importlib._bootstrap_external>", line 678, in exec_module
  File "<frozen importlib._bootstrap>", line 219, in _call_with_frames_removed
  File "/home/ubuntu/ScheduleBrewer/ScheduleBrewer/ScheduleBrewer/urls.py", line 18, in <module>
    from CourseBrowser import views
  File "/home/ubuntu/ScheduleBrewer/ScheduleBrewer/CourseBrowser/views.py", line 73
    logger.info("else")
                      ^
TabError: inconsistent use of tabs and spaces in indentation
